Workbook
Name ConSchematicLib: Config!$B$7
Name CSchematicLib: Config!$B$4
Name LSchematicLib: Config!$B$5
Name LSchematicLib.: Config!$B$5
Name PrivateLibraryPath: Config!$B$8

Sheet Start
A1: Altium Library database
A3: This spreadsheet contains the database for the daniw Altium library.
A6: Sheets:
A7: Start | B7: General information about the library
A8: Config | B8: Configuration of schematic symbol drawing style
A9: R | B9: Resistors
A10: C | B10: Capacitors
A11: L | B11: Inductors including CMC
A12: D | B12: Diodes
A13: CON | B13: Connectors
A14: Logic | B14: Logic
A15: Module | B15: Modules
A16: Integrated | B16: Integrated Circuits of any kind
A17: Misc | B17: Mechanical, Solderjumper, etc
A19: Columns:
A20: Part Number | C20: Unique part number for each part
A21: Comment | C21: Comment to be displayed on schematic
A22: Description | C22: Description with more information about the type of component
A23: Manufacturer | C23: Manufacturer
A24: Package | C24: Package name
A25: Value
A26: Library Path | C26: Path to the schematic symbol
A27: Library Ref | C27: File for the schematic symbol
A28: Footprint Path | C28: Path to the footprint
A29: Footprint Ref | C29: File for the footprint
A30: Absolute Value
A31: HelpURL | C31: Link to the datasheet
A32: Manufacturer 1 | C32: Manufacturer for supplier option 1
A33: Manufacturer Part Number 1 | C33: Manufacturer part number for supplier option 1
A34: Supplier 1 | C34: Supplier for supplier option 1
A35: Supplier Part Number 1 | C35: Supplier part number for supplier option 1
A36: Manufacturer 2 | C36: Manufacturer for supplier option 2
A37: Manufacturer Part Number 2 | C37: Manufacturer part number for supplier option 2
A38: Supplier 2 | C38: Supplier for supplier option 2
A39: Supplier Part Number 2 | C39: Supplier part number for supplier option 2
A43: IC Naming Convention
A44: SOP + Pitch P + Lead Span Nominal X height - Pin Qty -[TH Width X Length]
A45: Pin one is according to IPC always Top Left or Top Center

Sheet Config
A1: Library configuration
A3: Resistor symbol | B3: SCH/R_IEC.SchLib
A4: Capacitor symbol | B4: SCH/C_IEC.SchLib
A5: Inductor symbol | B5: SCH/L_ANSI.SchLib
A6: Logic symbol | B6: SCH/Logic_IEC.SchLib
A7: Connector symbol | B7: SCH/Connector.SchLib
A8: Private Library Path | B8: ../altium_lib_private/
A100: Resistor symbol list | B100: SCH/R_IEC.SchLib
B101: SCH/R_ANSI.SchLib
A110: Capacitor symbol list | B110: SCH/C_IEC.SchLib
B111: SCH/C_ANSI.SchLib
A120: Inductor symbol list | B120: SCH/L_IEC.SchLib
B121: SCH/L_ANSI.SchLib
A130: Logic symbol | B130: SCH/Logic_IEC.SchLib
B131: SCH/Logic_ANSI.SchLib
B132: SCH/Logic_DIN.SchLib
A140: Connector symbol | B140: SCH/Con_Box.SchLib
B141: SCH/Con_Circ.SchLib
B142: SCH/Connector.SchLib

Sheet R
A1: Part Number | B1: Comment | C1: Description | D1: Manufacturer | E1: Package | F1: Value | G1: Library Path | H1: Library Ref | I1: Footprint Path | J1: Footprint Ref | K1: Footprint Path 2 | L1: Footprint Ref 2 | M1: Absolute Value | N1: HelpURL | O1: Manufacturer 1 | P1: Manufacturer Part Number 1 | Q1: Supplier 1 | R1: Supplier Part Number 1 | S1: Manufacturer 2 | T1: Manufacturer Part Number 2 | U1: Supplier 2 | V1: Supplier Part Number 2 | W1: Manufacturer 3 | X1: Manufacturer Part Number 3 | Y1: Supplier 3 | Z1: Supplier Part Number 3 | AA1: JLC Type | AB1: Eurocircuits GPN
A2: 0R/0402 | B2: 0R/0402 | C2: RES SM 0402 0R | D2: GENERIC | E2: 0402 | F2: 0R | G2: =Config!$B$3 -> SCH/R_IEC.SchLib | H2: R | I2: PCB/SMT_CHIP.PcbLib | J2: R0402-0.35-WW | M2: 0 | N2: https://www.yageogroup.com/content/datasheet/asset/file/PYU-RC_GROUP_51_ROHS_L | O2: YAGEO | P2: RC0402FR-070RL | Q2: Digi-Key | R2: 311-0.0LRCT-ND | AB2: ="GPR"&E2&F2 -> GPR04020R
A3: 1R/0402 | B3: 1R/0402 | C3: RES SM 0402 1R | D3: GENERIC | E3: 0402 | F3: 1R | G3: =Config!$B$3 -> SCH/R_IEC.SchLib | H3: R | I3: PCB/SMT_CHIP.PcbLib | J3: R0402-0.35-WW | M3: 1 | N3: https://www.yageogroup.com/content/datasheet/asset/file/PYU-RC_GROUP_51_ROHS_L | O3: YAGEO | P3: RC0402FR-131RL | Q3: Digi-Key | R3: 13-RC0402FR-131RLCT-ND | S3: YAGEO | T3: RC0402FR-071RL | U3: Digi-Key | V3: 311-1.00LRCT-ND | AB3: ="GPR"&E3&F3 -> GPR04021R
A4: 1R1/0402 | B4: 1R1/0402 | C4: RES SM 0402 1R1 | D4: GENERIC | E4: 0402 | F4: 1R1 | G4: =Config!$B$3 -> SCH/R_IEC.SchLib | H4: R | I4: PCB/SMT_CHIP.PcbLib | J4: R0402-0.35-WW | M4: 1.1 | N4: https://www.yageogroup.com/content/datasheet/asset/file/PYU-RC_GROUP_51_ROHS_L | O4: YAGEO | P4: RC0402FR-071R1L | Q4: Digi-Key | R4: 13-RC0402FR-071R1LCT-ND | AB4: ="GPR"&E4&F4 -> GPR04021R1
A5: 1R2/0402 | B5: 1R2/0402 | C5: RES SM 0402 1R2 | D5: GENERIC | E5: 0402 | F5: 1R2 | G5: =Config!$B$3 -> SCH/R_IEC.SchLib | H5: R | I5: PCB/SMT_CHIP.PcbLib | J5: R0402-0.35-WW | M5: 1.2 | N5: https://www.yageogroup.com/content/datasheet/asset/file/PYU-RC_GROUP_51_ROHS_L | O5: YAGEO | P5: RC0402FR-071R2L | Q5: Digi-Key | R5: 13-RC0402FR-071R2LCT-ND | S5: YAGEO | T5: RC0402FR-7W1R2L | U5: Digi-Key | V5: 13-RC0402FR-7W1R2LCT-ND | AB5: ="GPR"&E5&F5 -> GPR04021R2
A6: 1R3/0402 | B6: 1R3/0402 | C6: RES SM 0402 1R3 | D6: GENERIC | E6: 0402 | F6: 1R3 | G6: =Config!$B$3 -> SCH/R_IEC.SchLib | H6: R | I6: PCB/SMT_CHIP.PcbLib | J6: R0402-0.35-WW | M6: 1.3 | N6: https://www.yageogroup.com/content/datasheet/asset/file/PYU-RC_GROUP_51_ROHS_L | O6: YAGEO | P6: RC0402FR-071R3L | Q6: Digi-Key | R6: 13-RC0402FR-071R3LCT-ND | AB6: ="GPR"&E6&F6 -> GPR04021R3
A7: 1R5/0402 | B7: 1R5/0402 | C7: RES SM 0402 1R5 | D7: GENERIC | E7: 0402 | F7: 1R5 | G7: =Config!$B$3 -> SCH/R_IEC.SchLib | H7: R | I7: PCB/SMT_CHIP.PcbLib | J7: R0402-0.35-WW | M7: 1.5 | N7: https://www.yageogroup.com/content/datasheet/asset/file/PYU-RC_GROUP_51_ROHS_L | O7: YAGEO | P7: RC0402FR-071R5L | Q7: Digi-Key | R7: 311-1.50LRCT-ND | AB7: ="GPR"&E7&F7 -> GPR04021R5
A8: 1R6/0402 | B8: 1R6/0402 | C8: RES SM 0402 1R6 | D8: GENERIC | E8: 0402 | F8: 1R6 | G8: =Config!$B$3 -> SCH/R_IEC.SchLib | H8: R | I8: PCB/SMT_CHIP.PcbLib | J8: R0402-0.35-WW | M8: 1.6 | N8: https://www.yageogroup.com/content/datasheet/asset/file/PYU-RC_GROUP_51_ROHS_L | O8: YAGEO | P8: RC0402FR-071R6L | Q8: Digi-Key | R8: 13-RC0402FR-071R6LCT-ND | AB8: ="GPR"&E8&F8 -> GPR04021R6
A9: 1R8/0402 | B9: 1R8/0402 | C9: RES SM 0402 1R8 | D9: GENERIC | E9: 0402 | F9: 1R8 | G9: =Config!$B$3 -> SCH/R_IEC.SchLib | H9: R | I9: PCB/SMT_CHIP.PcbLib | J9: R0402-0.35-WW | M9: 1.8 | N9: https://www.yageogroup.com/content/datasheet/asset/file/PYU-RC_GROUP_51_ROHS_L | O9: YAGEO | P9: RC0402FR-071R8L | Q9: Digi-Key | R9: 13-RC0402FR-071R8LCT-ND | AB9: ="GPR"&E9&F9 -> GPR04021R8
A10: 2R/0402 | B10: 2R/0402 | C10: RES SM 0402 2R | D10: GENERIC | E10: 0402 | F10: 2R | G10: =Config!$B$3 -> SCH/R_IEC.SchLib | H10: R | I10: PCB/SMT_CHIP.PcbLib | J10: R0402-0.35-WW | M10: 2 | N10: https://www.yageogroup.com/content/datasheet/asset/file/PYU-RC_GROUP_51_ROHS_L | O10: YAGEO | P10: RC0402FR-072RL | Q10: Digi-Key | R10: YAG3369CT-ND | AB10: ="GPR"&E10&F10 -> GPR04022R
A11: 2R2/0402 | B11: 2R2/0402 | C11: RES SM 0402 2R2 | D11: GENERIC | E11: 0402 | F11: 2R2 | G11: =Config!$B$3 -> SCH/R_IEC.SchLib | H11: R | I11: PCB/SMT_CHIP.PcbLib | J11: R0402-0.35-WW | M11: 2.2 | N11: https://www.yageogroup.com/content/datasheet/asset/file/PYU-RC_GROUP_51_ROHS_L | O11: YAGEO | P11: RC0402FR-132R2L | Q11: Digi-Key | R11: 13-RC0402FR-132R2LCT-ND | S11: YAGEO | T11: RC0402FR-072R2L | U11: Digi-Key | V11: 311-2.20LRCT-ND | AB11: ="GPR"&E11&F11 -> GPR04022R2
A12: 2R4/0402 | B12: 2R4/0402 | C12: RES SM 0402 2R4 | D12: GENERIC | E12: 0402 | F12: 2R4 | G12: =Config!$B$3 -> SCH/R_IEC.SchLib | H12: R | I12: PCB/SMT_CHIP.PcbLib | J12: R0402-0.35-WW | M12: 2.4 | N12: https://www.yageogroup.com/content/datasheet/asset/file/PYU-RC_GROUP_51_ROHS_L | O12: YAGEO | P12: RC0402FR-072R4L | Q12: Digi-Key | R12: 13-RC0402FR-072R4LCT-ND | AB12: ="GPR"&E12&F12 -> GPR04022R4
A13: 2R7/0402 | B13: 2R7/0402 | C13: RES SM 0402 2R7 | D13: GENERIC | E13: 0402 | F13: 2R7 | G13: =Config!$B$3 -> SCH/R_IEC.SchLib | H13: R | I13: PCB/SMT_CHIP.PcbLib | J13: R0402-0.35-WW | M13: 2.7 | N13: https://www.yageogroup.com/content/datasheet/asset/file/PYU-RC_GROUP_51_ROHS_L | O13: YAGEO | P13: RC0402FR-072R7L | Q13: Digi-Key | R13: 13-RC0402FR-072R7LCT-ND | S13: YAGEO | T13: RC0402FR-7W2R7L | U13: Digi-Key | V13: 13-RC0402FR-7W2R7LCT-ND | AB13: ="GPR"&E13&F13 -> GPR04022R7
A14: 3R/0402 | B14: 3R/0402 | C14: RES SM 0402 3R | D14: GENERIC | E14: 0402 | F14: 3R | G14: =Config!$B$3 -> SCH/R_IEC.SchLib | H14: R | I14: PCB/SMT_CHIP.PcbLib | J14: R0402-0.35-WW | M14: 3 | N14: https://www.yageogroup.com/content/datasheet/asset/file/PYU-RC_GROUP_51_ROHS_L | O14: YAGEO | P14: RC0402FR-133RL | Q14: Digi-Key | R14: 13-RC0402FR-133RLCT-ND | S14: YAGEO | T14: RC0402FR-073RL | U14: Digi-Key | V14: 13-RC0402FR-073RLCT-ND | AB14: ="GPR"&E14&F14 -> GPR04023R
A15: 3R3/0402 | B15: 3R3/0402 | C15: RES SM 0402 3R3 | D15: GENERIC | E15: 0402 | F15: 3R3 | G15: =Config!$B$3 -> SCH/R_IEC.SchLib | H15: R | I15: PCB/SMT_CHIP.PcbLib | J15: R0402-0.35-WW | M15: 3.3 | N15: https://www.yageogroup.com/content/datasheet/asset/file/PYU-RC_GROUP_51_ROHS_L | O15: YAGEO | P15: RC0402FR-133R3L | Q15: Digi-Key | R15: 13-RC0402FR-133R3LCT-ND | S15: YAGEO | T15: RC0402FR-073R3L | U15: Digi-Key | V15: 311-3.30LRCT-ND | AB15: ="GPR"&E15&F15 -> GPR04023R3
A16: 3R6/0402 | B16: 3R6/0402 | C16: RES SM 0402 3R6 | D16: GENERIC | E16: 0402 | F16: 3R6 | G16: =Config!$B$3 -> SCH/R_IEC.SchLib | H16: R | I16: PCB/SMT_CHIP.PcbLib | J16: R0402-0.35-WW | M16: 3.6 | N16: https://www.yageogroup.com/content/datasheet/asset/file/PYU-RC_GROUP_51_ROHS_L | O16: YAGEO | P16: RC0402FR-073R6L | Q16: Digi-Key | R16: 13-RC0402FR-073R6LCT-ND | AB16: ="GPR"&E16&F16 -> GPR04023R6
A17: 3R9/0402 | B17: 3R9/0402 | C17: RES SM 0402 3R9 | D17: GENERIC | E17: 0402 | F17: 3R9 | G17: =Config!$B$3 -> SCH/R_IEC.SchLib | H17: R | I17: PCB/SMT_CHIP.PcbLib | J17: R0402-0.35-WW | M17: 3.9 | N17: https://www.yageogroup.com/content/datasheet/asset/file/PYU-RC_GROUP_51_ROHS_L | O17: YAGEO | P17: RC0402FR-073R9L | Q17: Digi-Key | R17: 13-RC0402FR-073R9LCT-ND | AB17: ="GPR"&E17&F17 -> GPR04023R9
A18: 4R3/0402 | B18: 4R3/0402 | C18: RES SM 0402 4R3 | D18: GENERIC | E18: 0402 | F18: 4R3 | G18: =Config!$B$3 -> SCH/R_IEC.SchLib | H18: R | I18: PCB/SMT_CHIP.PcbLib | J18: R0402-0.35-WW | M18: 4.3 | N18: https://www.yageogroup.com/content/datasheet/asset/file/PYU-RC_GROUP_51_ROHS_L | O18: YAGEO | P18: RC0402FR-074R3L | Q18: Digi-Key | R18: 13-RC0402FR-074R3LCT-ND | AB18: ="GPR"&E18&F18 -> GPR04024R3
A19: 4R7/0402 | B19: 4R7/0402 | C19: RES SM 0402 4R7 | D19: GENERIC | E19: 0402 | F19: 4R7 | G19: =Config!$B$3 -> SCH/R_IEC.SchLib | H19: R | I19: PCB/SMT_CHIP.PcbLib | J19: R0402-0.35-WW | M19: 4.7 | N19: https://www.yageogroup.com/content/datasheet/asset/file/PYU-RC_GROUP_51_ROHS_L | O19: YAGEO | P19: RC0402FR-134R7L | Q19: Digi-Key | R19: 13-RC0402FR-134R7LCT-ND | S19: YAGEO | T19: RC0402FR-074R7L | U19: Digi-Key | V19: 311-4.70LRCT-ND | AB19: ="GPR"&E19&F19 -> GPR04024R7
A20: 5R1/0402 | B20: 5R1/0402 | C20: RES SM 0402 5R1 | D20: GENERIC | E20: 0402 | F20: 5R1 | G20: =Config!$B$3 -> SCH/R_IEC.SchLib | H20: R | I20: PCB/SMT_CHIP.PcbLib | J20: R0402-0.35-WW | M20: 5.1 | N20: https://www.yageogroup.com/content/datasheet/asset/file/PYU-RC_GROUP_51_ROHS_L | O20: YAGEO | P20: RC0402FR-075R1L | Q20: Digi-Key | R20: YAG3370CT-ND | AB20: ="GPR"&E20&F20 -> GPR04025R1
A21: 5R6/0402 | B21: 5R6/0402 | C21: RES SM 0402 5R6 | D21: GENERIC | E21: 0402 | F21: 5R6 | G21: =Config!$B$3 -> SCH/R_IEC.SchLib | H21: R | I21: PCB/SMT_CHIP.PcbLib | J21: R0402-0.35-WW | M21: 5.6 | N21: https://www.yageogroup.com/content/datasheet/asset/file/PYU-RC_GROUP_51_ROHS_L | O21: YAGEO | P21: RC0402FR-075R6L | Q21: Digi-Key | R21: 13-RC0402FR-075R6LCT-ND | AB21: ="GPR"&E21&F21 -> GPR04025R6
A22: 6R2/0402 | B22: 6R2/0402 | C22: RES SM 0402 6R2 | D22: GENERIC | E22: 0402 | F22: 6R2 | G22: =Config!$B$3 -> SCH/R_IEC.SchLib | H22: R | I22: PCB/SMT_CHIP.PcbLib | J22: R0402-0.35-WW | M22: 6.2 | N22: https://www.yageogroup.com/content/datasheet/asset/file/PYU-RC_GROUP_51_ROHS_L | O22: YAGEO | P22: RC0402FR-076R2L | Q22: Digi-Key | R22: 13-RC0402FR-076R2LCT-ND | AB22: ="GPR"&E22&F22 -> GPR04026R2
A23: 6R8/0402 | B23: 6R8/0402 | C23: RES SM 0402 6R8 | D23: GENERIC | E23: 0402 | F23: 6R8 | G23: =Config!$B$3 -> SCH/R_IEC.SchLib | H23: R | I23: PCB/SMT_CHIP.PcbLib | J23: R0402-0.35-WW | M23: 6.8 | N23: https://www.yageogroup.com/content/datasheet/asset/file/PYU-RC_GROUP_51_ROHS_L | O23: YAGEO | P23: RC0402FR-076R8L | Q23: Digi-Key | R23: 13-RC0402FR-076R8LCT-ND | AB23: ="GPR"&E23&F23 -> GPR04026R8
A24: 7R5/0402 | B24: 7R5/0402 | C24: RES SM 0402 7R5 | D24: GENERIC | E24: 0402 | F24: 7R5 | G24: =Config!$B$3 -> SCH/R_IEC.SchLib | H24: R | I24: PCB/SMT_CHIP.PcbLib | J24: R0402-0.35-WW | M24: 7.5 | N24: https://www.yageogroup.com/content/datasheet/asset/file/PYU-RC_GROUP_51_ROHS_L | O24: YAGEO | P24: RC0402FR-077R5L | Q24: Digi-Key | R24: 13-RC0402FR-077R5LCT-ND | AB24: ="GPR"&E24&F24 -> GPR04027R5
A25: 8R2/0402 | B25: 8R2/0402 | C25: RES SM 0402 8R2 | D25: GENERIC | E25: 0402 | F25: 8R2 | G25: =Config!$B$3 -> SCH/R_IEC.SchLib | H25: R | I25: PCB/SMT_CHIP.PcbLib | J25: R0402-0.35-WW | M25: 8.2 | N25: https://www.yageogroup.com/content/datasheet/asset/file/PYU-RC_GROUP_51_ROHS_L | O25: YAGEO | P25: RC0402FR-078R2L | Q25: Digi-Key | R25: 13-RC0402FR-078R2LCT-ND | AB25: ="GPR"&E25&F25 -> GPR04028R2
A26: 9R1/0402 | B26: 9R1/0402 | C26: RES SM 0402 9R1 | D26: GENERIC | E26: 0402 | F26: 9R1 | G26: =Config!$B$3 -> SCH/R_IEC.SchLib | H26: R | I26: PCB/SMT_CHIP.PcbLib | J26: R0402-0.35-WW | M26: 9.1 | N26: https://www.yageogroup.com/content/datasheet/asset/file/PYU-RC_GROUP_51_ROHS_L | O26: YAGEO | P26: RC0402FR-079R1L | Q26: Digi-Key | R26: 13-RC0402FR-079R1LCT-ND | AB26: ="GPR"&E26&F26 -> GPR04029R1
A27: 10R/0402 | B27: 10R/0402 | C27: RES SM 0402 10R | D27: GENERIC | E27: 0402 | F27: 10R | G27: =Config!$B$3 -> SCH/R_IEC.SchLib | H27: R | I27: PCB/SMT_CHIP.PcbLib | J27: R0402-0.35-WW | M27: 10 | N27: https://www.yageogroup.com/content/datasheet/asset/file/PYU-RC_GROUP_51_ROHS_L | O27: YAGEO | P27: RC0402FR-1310RL | Q27: Digi-Key | R27: 13-RC0402FR-1310RLCT-ND | S27: YAGEO | T27: RC0402FR-1010RL | U27: Digi-Key | V27: 13-RC0402FR-1010RLCT-ND | AB27: ="GPR"&E27&F27 -> GPR040210R
A28: 11R/0402 | B28: 11R/0402 | C28: RES SM 0402 11R | D28: GENERIC | E28: 0402 | F28: 11R | G28: =Config!$B$3 -> SCH/R_IEC.SchLib | H28: R | I28: PCB/SMT_CHIP.PcbLib | J28: R0402-0.35-WW | M28: 11 | N28: https://www.yageogroup.com/content/datasheet/asset/file/PYU-RC_GROUP_51_ROHS_L | O28: YAGEO | P28: RC0402FR-0711RL | Q28: Digi-Key | R28: YAG2962CT-ND | AB28: ="GPR"&E28&F28 -> GPR040211R
A29: 12R/0402 | B29: 12R/0402 | C29: RES SM 0402 12R | D29: GENERIC | E29: 0402 | F29: 12R | G29: =Config!$B$3 -> SCH/R_IEC.SchLib | H29: R | I29: PCB/SMT_CHIP.PcbLib | J29: R0402-0.35-WW | M29: 12 | N29: https://www.yageogroup.com/content/datasheet/asset/file/PYU-RC_GROUP_51_ROHS_L | O29: YAGEO | P29: RC0402FR-1312RL | Q29: Digi-Key | R29: 13-RC0402FR-1312RLCT-ND | S29: YAGEO | T29: RC0402FR-0712RL | U29: Digi-Key | V29: YAG2968CT-ND | AB29: ="GPR"&E29&F29 -> GPR040212R
A30: 13R/0402 | B30: 13R/0402 | C30: RES SM 0402 13R | D30: GENERIC | E30: 0402 | F30: 13R | G30: =Config!$B$3 -> SCH/R_IEC.SchLib | H30: R | I30: PCB/SMT_CHIP.PcbLib | J30: R0402-0.35-WW | M30: 13 | N30: https://www.yageogroup.com/content/datasheet/asset/file/PYU-RC_GROUP_51_ROHS_L | O30: YAGEO | P30: RC0402FR-0713RL | Q30: Digi-Key | R30: YAG2977CT-ND | AB30: ="GPR"&E30&F30 -> GPR040213R
A31: 15R/0402 | B31: 15R/0402 | C31: RES SM 0402 15R | D31: GENERIC | E31: 0402 | F31: 15R | G31: =Config!$B$3 -> SCH/R_IEC.SchLib | H31: R | I31: PCB/SMT_CHIP.PcbLib | J31: R0402-0.35-WW | M31: 15 | N31: https://www.yageogroup.com/content/datasheet/asset/file/PYU-RC_GROUP_51_ROHS_L | O31: YAGEO | P31: RC0402FR-1315RL | Q31: Digi-Key | R31: 13-RC0402FR-1315RLCT-ND | S31: YAGEO | T31: RC0402FR-0715RL | U31: Digi-Key | V31: 311-15LRCT-ND | AB31: ="GPR"&E31&F31 -> GPR040215R
A32: 16R/0402 | B32: 16R/0402 | C32: RES SM 0402 16R | D32: GENERIC | E32: 0402 | F32: 16R | G32: =Config!$B$3 -> SCH/R_IEC.SchLib | H32: R | I32: PCB/SMT_CHIP.PcbLib | J32: R0402-0.35-WW | M32: 16 | N32: https://www.yageogroup.com/content/datasheet/asset/file/PYU-RC_GROUP_51_ROHS_L | O32: YAGEO | P32: RC0402FR-0716RL | Q32: Digi-Key | R32: YAG3007CT-ND | AB32: ="GPR"&E32&F32 -> GPR040216R
A33: 18R/0402 | B33: 18R/0402 | C33: RES SM 0402 18R | D33: GENERIC | E33: 0402 | F33: 18R | G33: =Config!$B$3 -> SCH/R_IEC.SchLib | H33: R | I33: PCB/SMT_CHIP.PcbLib | J33: R0402-0.35-WW | M33: 18 | N33: https://www.yageogroup.com/content/datasheet/asset/file/PYU-RC_GROUP_51_ROHS_L | O33: YAGEO | P33: RC0402FR-1318RL | Q33: Digi-Key | R33: 13-RC0402FR-1318RLCT-ND | S33: YAGEO | T33: RC0402FR-0718RL | U33: Digi-Key | V33: YAG3021CT-ND | AB33: ="GPR"&E33&F33 -> GPR040218R
A34: 20R/0402 | B34: 20R/0402 | C34: RES SM 0402 20R | D34: GENERIC | E34: 0402 | F34: 20R | G34: =Config!$B$3 -> SCH/R_IEC.SchLib | H34: R | I34: PCB/SMT_CHIP.PcbLib | J34: R0402-0.35-WW | M34: 20 | N34: https://www.yageogroup.com/content/datasheet/asset/file/PYU-RC_GROUP_51_ROHS_L | O34: YAGEO | P34: RC0402FR-1320RL | Q34: Digi-Key | R34: 13-RC0402FR-1320RLCT-ND | S34: YAGEO | T34: RC0402FR-0720RL | U34: Digi-Key | V34: 311-20LRCT-ND | AB34: ="GPR"&E34&F34 -> GPR040220R
A35: 22R/0402 | B35: 22R/0402 | C35: RES SM 0402 22R | D35: GENERIC | E35: 0402 | F35: 22R | G35: =Config!$B$3 -> SCH/R_IEC.SchLib | H35: R | I35: PCB/SMT_CHIP.PcbLib | J35: R0402-0.35-WW | M35: 22 | N35: https://www.yageogroup.com/content/datasheet/asset/file/PYU-RC_GROUP_51_ROHS_L | O35: YAGEO | P35: RC0402FR-1322RL | Q35: Digi-Key | R35: 13-RC0402FR-1322RLCT-ND | S35: YAGEO | T35: RC0402FR-1022RL | U35: Digi-Key | V35: 13-RC0402FR-1022RLCT-ND | AB35: ="GPR"&E35&F35 -> GPR040222R
A36: 24R/0402 | B36: 24R/0402 | C36: RES SM 0402 24R | D36: GENERIC | E36: 0402 | F36: 24R | G36: =Config!$B$3 -> SCH/R_IEC.SchLib | H36: R | I36: PCB/SMT_CHIP.PcbLib | J36: R0402-0.35-WW | M36: 24 | N36: https://www.yageogroup.com/content/datasheet/asset/file/PYU-RC_GROUP_51_ROHS_L | O36: YAGEO | P36: RC0402FR-1324RL | Q36: Digi-Key | R36: 13-RC0402FR-1324RLCT-ND | S36: YAGEO | T36: RC0402FR-0724RL | U36: Digi-Key | V36: YAG3073CT-ND | AB36: ="GPR"&E36&F36 -> GPR040224R
A37: 27R/0402 | B37: 27R/0402 | C37: RES SM 0402 27R | D37: GENERIC | E37: 0402 | F37: 27R | G37: =Config!$B$3 -> SCH/R_IEC.SchLib | H37: R | I37: PCB/SMT_CHIP.PcbLib | J37: R0402-0.35-WW | M37: 27 | N37: https://www.yageogroup.com/content/datasheet/asset/file/PYU-RC_GROUP_51_ROHS_L | O37: YAGEO | P37: RC0402FR-1327RL | Q37: Digi-Key | R37: 13-RC0402FR-1327RLCT-ND | S37: YAGEO | T37: RC0402FR-0727RL | U37: Digi-Key | V37: YAG3086CT-ND | AB37: ="GPR"&E37&F37 -> GPR040227R
A38: 30R/0402 | B38: 30R/0402 | C38: RES SM 0402 30R | D38: GENERIC | E38: 0402 | F38: 30R | G38: =Config!$B$3 -> SCH/R_IEC.SchLib | H38: R | I38: PCB/SMT_CHIP.PcbLib | J38: R0402-0.35-WW | M38: 30 | N38: https://www.yageogroup.com/content/datasheet/asset/file/PYU-RC_GROUP_51_ROHS_L | O38: YAGEO | P38: RC0402FR-1330RL | Q38: Digi-Key | R38: 13-RC0402FR-1330RLCT-ND | S38: YAGEO | T38: RC0402FR-0730RL | U38: Digi-Key | V38: 311-30LRCT-ND | AB38: ="GPR"&E38&F38 -> GPR040230R
A39: 33R/0402 | B39: 33R/0402 | C39: RES SM 0402 33R | D39: GENERIC | E39: 0402 | F39: 33R | G39: =Config!$B$3 -> SCH/R_IEC.SchLib | H39: R | I39: PCB/SMT_CHIP.PcbLib | J39: R0402-0.35-WW | M39: 33 | N39: https://www.yageogroup.com/content/datasheet/asset/file/PYU-RC_GROUP_51_ROHS_L | O39: YAGEO | P39: RC0402FR-1333RL | Q39: Digi-Key | R39: 13-RC0402FR-1333RLCT-ND | S39: YAGEO | T39: RC0402FR-0733RL | U39: Digi-Key | V39: 311-33.0LRCT-ND | AB39: ="GPR"&E39&F39 -> GPR040233R
A40: 36R/0402 | B40: 36R/0402 | C40: RES SM 0402 36R | D40: GENERIC | E40: 0402 | F40: 36R | G40: =Config!$B$3 -> SCH/R_IEC.SchLib | H40: R | I40: PCB/SMT_CHIP.PcbLib | J40: R0402-0.35-WW | M40: 36 | N40: https://www.yageogroup.com/content/datasheet/asset/file/PYU-RC_GROUP_51_ROHS_L | O40: YAGEO | P40: RC0402FR-1336RL | Q40: Digi-Key | R40: 13-RC0402FR-1336RLCT-ND | S40: YAGEO | T40: RC0402FR-0736RL | U40: Digi-Key | V40: 311-36.0LRCT-ND | AB40: ="GPR"&E40&F40 -> GPR040236R
...

Sheet C
A1: Part Number | B1: Comment | C1: Description | D1: Manufacturer | E1: Package | F1: Value | G1: Library Path | H1: Library Ref | I1: Footprint Path | J1: Footprint Ref | K1: Absolute Value | L1: HelpURL | M1: Manufacturer 1 | N1: Manufacturer Part Number 1 | O1: Supplier 1 | P1: Supplier Part Number 1 | Q1: Manufacturer 2 | R1: Manufacturer Part Number 2 | S1: Supplier 2 | T1: Supplier Part Number 2 | U1: Manufacturer 3 | V1: Manufacturer Part Number 3 | W1: Supplier 3 | X1: Supplier Part Number 3 | Y1: JLC Type | Z1: Eurocircuits GPN
A2: 1P/0603/50V/C0G | B2: 1P/0603/50V/C0G | C2: CAP SM 0603 1.0pF 50V C0G | D2: GENERIC | E2: 0603 | F2: 1.0pF | G2: =Config!$B$4 -> SCH/C_IEC.SchLib | H2: C | I2: PCB/SMT_CHIP.PcbLib | J2: CAP0603_C0G | K2: 1e-12 | L2: https://www.yageo.com/upload/media/product/productsearch/datasheet/mlcc/UPY-GP_NP0_16V-to-50V_18.pdf | M2: YAGEO | N2: CC0603CRNPO9BN1R0 | O2: Digi-Key | P2: 311-1049-1-ND | Q2: YAGEO | R2: CC0603BRNPO9BN1R0 | S2: Digi-Key | T2: 311-3346-1-ND | Z2: GPC06031R0-C0G
A3: 1P2/0603/50V/C0G | B3: 1P2/0603/50V/C0G | C3: CAP SM 0603 1.2pF 50V C0G | D3: GENERIC | E3: 0603 | F3: 1.2pF | G3: =Config!$B$4 -> SCH/C_IEC.SchLib | H3: C | I3: PCB/SMT_CHIP.PcbLib | J3: CAP0603_C0G | K3: 1.2e-12 | L3: https://www.yageo.com/upload/media/product/productsearch/datasheet/mlcc/UPY-GP_NP0_16V-to-50V_18.pdf | M3: YAGEO | N3: CC0603CRNPO9BN1R2 | O3: Digi-Key | P3: 311-3851-1-ND | Q3: YAGEO | R3: CC0603BRNPO9BN1R2 | S3: Digi-Key | T3: 311-3825-1-ND | Z3: GPC06031R2-C0G
A4: 1P5/0603/50V/C0G | B4: 1P5/0603/50V/C0G | C4: CAP SM 0603 1.5pF 50V C0G | D4: GENERIC | E4: 0603 | F4: 1.5pF | G4: =Config!$B$4 -> SCH/C_IEC.SchLib | H4: C | I4: PCB/SMT_CHIP.PcbLib | J4: CAP0603_C0G | K4: 1.5e-12 | L4: https://www.yageo.com/upload/media/product/productsearch/datasheet/mlcc/UPY-GP_NP0_16V-to-50V_18.pdf | M4: YAGEO | N4: CC0603CRNPO9BN1R5 | O4: Digi-Key | P4: 311-1050-1-ND | Q4: YAGEO | R4: CC0603BRNPO9BN1R5 | S4: Digi-Key | T4: 311-1737-1-ND | Z4: GPC06031R5-C0G
A5: 1P8/0603/50V/C0G | B5: 1P8/0603/50V/C0G | C5: CAP SM 0603 1.8pF 50V C0G | D5: GENERIC | E5: 0603 | F5: 1.8pF | G5: =Config!$B$4 -> SCH/C_IEC.SchLib | H5: C | I5: PCB/SMT_CHIP.PcbLib | J5: CAP0603_C0G | K5: 1.8e-12 | L5: https://www.yageo.com/upload/media/product/productsearch/datasheet/mlcc/UPY-GP_NP0_16V-to-50V_18.pdf | M5: YAGEO | N5: CC0603CRNPO9BN1R8 | O5: Digi-Key | P5: 311-3852-1-ND | Q5: YAGEO | R5: CC0603BRNPO9BN1R8 | S5: Digi-Key | T5: 311-3826-1-ND | Z5: GPC06031R8-C0G
A6: 2P2/0603/50V/C0G | B6: 2P2/0603/50V/C0G | C6: CAP SM 0603 2.2pF 50V C0G | D6: GENERIC | E6: 0603 | F6: 2.2pF | G6: =Config!$B$4 -> SCH/C_IEC.SchLib | H6: C | I6: PCB/SMT_CHIP.PcbLib | J6: CAP0603_C0G | K6: 2.2e-12 | L6: https://www.yageo.com/upload/media/product/productsearch/datasheet/mlcc/UPY-GP_NP0_16V-to-50V_18.pdf | M6: YAGEO | N6: CC0603CRNPO9BN2R2 | O6: Digi-Key | P6: 311-1739-1-ND | Q6: YAGEO | R6: CC0603DRNPO9BN2R2 | S6: Digi-Key | T6: 311-3870-1-ND | Z6: GPC06032R2-C0G
A7: 2P7/0603/50V/C0G | B7: 2P7/0603/50V/C0G | C7: CAP SM 0603 2.7pF 50V C0G | D7: GENERIC | E7: 0603 | F7: 2.7pF | G7: =Config!$B$4 -> SCH/C_IEC.SchLib | H7: C | I7: PCB/SMT_CHIP.PcbLib | J7: CAP0603_C0G | K7: 2.7e-12 | L7: https://www.yageo.com/upload/media/product/productsearch/datasheet/mlcc/UPY-GP_NP0_16V-to-50V_18.pdf | M7: YAGEO | N7: CC0603CRNPO9BN2R7 | O7: Digi-Key | P7: 311-3854-1-ND | Q7: YAGEO | R7: CC0603BRNPO9BN2R7 | S7: Digi-Key | T7: 311-3830-1-ND | Z7: GPC06032R7-C0G
A8: 3P3/0603/50V/C0G | B8: 3P3/0603/50V/C0G | C8: CAP SM 0603 3.3pF 50V C0G | D8: GENERIC | E8: 0603 | F8: 3.3pF | G8: =Config!$B$4 -> SCH/C_IEC.SchLib | H8: C | I8: PCB/SMT_CHIP.PcbLib | J8: CAP0603_C0G | K8: 3.3e-12 | L8: https://www.yageo.com/upload/media/product/productsearch/datasheet/mlcc/UPY-GP_NP0_16V-to-50V_18.pdf | M8: YAGEO | N8: CC0603CRNPO9BN3R3 | O8: Digi-Key | P8: 311-3855-1-ND | Q8: YAGEO | R8: CC0603BRNPO9BN3R3 | S8: Digi-Key | T8: 311-3832-1-ND | Z8: GPC06033R3-C0G
A9: 3P9/0603/50V/C0G | B9: 3P9/0603/50V/C0G | C9: CAP SM 0603 3.9pF 50V C0G | D9: GENERIC | E9: 0603 | F9: 3.9pF | G9: =Config!$B$4 -> SCH/C_IEC.SchLib | H9: C | I9: PCB/SMT_CHIP.PcbLib | J9: CAP0603_C0G | K9: 3.9e-12 | L9: https://www.yageo.com/upload/media/product/productsearch/datasheet/mlcc/UPY-GP_NP0_16V-to-50V_18.pdf | M9: YAGEO | N9: CC0603CRNPO9BN3R9 | O9: Digi-Key | P9: 311-3857-1-ND | Q9: YAGEO | R9: CC0603BRNPO9BN3R9 | S9: Digi-Key | T9: 311-3834-1-ND | Z9: GPC06033R9-C0G
A10: 4P7/0603/50V/C0G | B10: 4P7/0603/50V/C0G | C10: CAP SM 0603 4.7pF 50V C0G | D10: GENERIC | E10: 0603 | F10: 4.7pF | G10: =Config!$B$4 -> SCH/C_IEC.SchLib | H10: C | I10: PCB/SMT_CHIP.PcbLib | J10: CAP0603_C0G | K10: 4.7e-12 | L10: https://www.yageo.com/upload/media/product/productsearch/datasheet/mlcc/UPY-GP_NP0_16V-to-50V_18.pdf | M10: YAGEO | N10: CC0603CRNPO9BN4R7 | O10: Digi-Key | P10: 311-1740-1-ND | Q10: YAGEO | R10: CC0603DRNPO9BN4R7 | S10: Digi-Key | T10: 13-CC0603DRNPO9BN4R7CT-ND | U10: HRE | V10: CGA0603C0G4R7C500JT | W10: LCSC | X10: C41361238 | Z10: GPC06034R7-C0G
A11: 5P6/0603/50V/C0G | B11: 5P6/0603/50V/C0G | C11: CAP SM 0603 5.6pF 50V C0G | D11: GENERIC | E11: 0603 | F11: 5.6pF | G11: =Config!$B$4 -> SCH/C_IEC.SchLib | H11: C | I11: PCB/SMT_CHIP.PcbLib | J11: CAP0603_C0G | K11: 5.6e-12 | L11: https://www.yageo.com/upload/media/product/productsearch/datasheet/mlcc/UPY-GP_NP0_16V-to-50V_18.pdf | M11: YAGEO | N11: CC0603DRNPO9BN5R6 | O11: Digi-Key | P11: 311-3872-1-ND | Q11: YAGEO | R11: CC0603CRNPO9BN5R6 | S11: Digi-Key | T11: 311-1741-1-ND | Z11: GPC06035R6-C0G
A12: 6P8/0603/50V/C0G | B12: 6P8/0603/50V/C0G | C12: CAP SM 0603 6.8pF 50V C0G | D12: GENERIC | E12: 0603 | F12: 6.8pF | G12: =Config!$B$4 -> SCH/C_IEC.SchLib | H12: C | I12: PCB/SMT_CHIP.PcbLib | J12: CAP0603_C0G | K12: 6.8e-12 | L12: https://www.yageo.com/upload/media/product/productsearch/datasheet/mlcc/UPY-GP_NP0_16V-to-50V_18.pdf | M12: YAGEO | N12: CC0603DRNPO9BN6R8 | O12: Digi-Key | P12: 311-3874-1-ND | Q12: YAGEO | R12: CC0603CRNPO9BN6R8 | S12: Digi-Key | T12: 311-3861-1-ND | Z12: GPC06036R8-C0G
A13: 8P2/0603/50V/C0G | B13: 8P2/0603/50V/C0G | C13: CAP SM 0603 8.2pF 50V C0G | D13: GENERIC | E13: 0603 | F13: 8.2pF | G13: =Config!$B$4 -> SCH/C_IEC.SchLib | H13: C | I13: PCB/SMT_CHIP.PcbLib | J13: CAP0603_C0G | K13: 8.2e-12 | L13: https://www.yageo.com/upload/media/product/productsearch/datasheet/mlcc/UPY-GP_NP0_16V-to-50V_18.pdf | M13: YAGEO | N13: CC0603DRNPO9BN8R2 | O13: Digi-Key | P13: 311-1742-1-ND | Q13: YAGEO | R13: CC0603JRNPO9BN8R2 | S13: Digi-Key | T13: 311-3977-1-ND | Z13: GPC06038R2-C0G
A14: 10P/0603/50V/C0G | B14: 10P/0603/50V/C0G | C14: CAP SM 0603 10pF 50V C0G | D14: GENERIC | E14: 0603 | F14: 10pF | G14: =Config!$B$4 -> SCH/C_IEC.SchLib | H14: C | I14: PCB/SMT_CHIP.PcbLib | J14: CAP0603_C0G | K14: 1e-11 | L14: https://www.yageo.com/upload/media/product/productsearch/datasheet/mlcc/UPY-GP_NP0_16V-to-50V_18.pdf | M14: YAGEO | N14: CC0603JRNPO9BN100 | O14: Digi-Key | P14: 311-1058-1-ND | Q14: YAGEO | R14: CC0603KRNPO9BN100 | S14: Digi-Key | T14: 311-4025-1-ND | U14: Samsung Electro-Mechanics | V14: CL10C100JB8NNNC | W14: LCSC | X14: C1634 | Z14: GPC0603100-C0G
A15: 12P/0603/50V/C0G | B15: 12P/0603/50V/C0G | C15: CAP SM 0603 12pF 50V C0G | D15: GENERIC | E15: 0603 | F15: 12pF | G15: =Config!$B$4 -> SCH/C_IEC.SchLib | H15: C | I15: PCB/SMT_CHIP.PcbLib | J15: CAP0603_C0G | K15: 1.2e-11 | L15: https://www.yageo.com/upload/media/product/productsearch/datasheet/mlcc/UPY-GP_NP0_16V-to-50V_18.pdf | M15: YAGEO | N15: CC0603JRNPO9BN120 | O15: Digi-Key | P15: 311-1059-1-ND | Q15: YAGEO | R15: CC0603KRNPO9BN120 | S15: Digi-Key | T15: 311-4027-1-ND | Z15: GPC0603120-C0G
A16: 15P/0603/50V/C0G | B16: 15P/0603/50V/C0G | C16: CAP SM 0603 15pF 50V C0G | D16: GENERIC | E16: 0603 | F16: 15pF | G16: =Config!$B$4 -> SCH/C_IEC.SchLib | H16: C | I16: PCB/SMT_CHIP.PcbLib | J16: CAP0603_C0G | K16: 1.5e-11 | L16: https://www.yageo.com/upload/media/product/productsearch/datasheet/mlcc/UPY-GP_NP0_16V-to-50V_18.pdf | M16: YAGEO | N16: CC0603JRNPO9BN150 | O16: Digi-Key | P16: 311-1060-1-ND | Q16: YAGEO | R16: CC0603KRNPO9BN150 | S16: Digi-Key | T16: 311-4028-1-ND | U16: Samsung Electro-Mechanics | V16: Samsung Electro-Mechanics | W16: LCSC | X16: C1644 | Y16: Basic | Z16: GPC0603150-C0G
A17: 18P/0603/50V/C0G | B17: 18P/0603/50V/C0G | C17: CAP SM 0603 18pF 50V C0G | D17: GENERIC | E17: 0603 | F17: 18pF | G17: =Config!$B$4 -> SCH/C_IEC.SchLib | H17: C | I17: PCB/SMT_CHIP.PcbLib | J17: CAP0603_C0G | K17: 1.8e-11 | L17: https://www.yageo.com/upload/media/product/productsearch/datasheet/mlcc/UPY-GP_NP0_16V-to-50V_18.pdf | M17: YAGEO | N17: CC0603JRNPO9BN180 | O17: Digi-Key | P17: 311-1061-1-ND | Q17: YAGEO | R17: CC0603KRNPO9BN180 | S17: Digi-Key | T17: 13-CC0603KRNPO9BN180CT-ND | Z17: GPC0603180-C0G
A18: 22P/0603/50V/C0G | B18: 22P/0603/50V/C0G | C18: CAP SM 0603 22pF 50V C0G | D18: GENERIC | E18: 0603 | F18: 22pF | G18: =Config!$B$4 -> SCH/C_IEC.SchLib | H18: C | I18: PCB/SMT_CHIP.PcbLib | J18: CAP0603_C0G | K18: 2.2e-11 | L18: https://www.yageo.com/upload/media/product/productsearch/datasheet/mlcc/UPY-GP_NP0_16V-to-50V_18.pdf | M18: YAGEO | N18: CC0603JRNPO9BN220 | O18: Digi-Key | P18: 311-1062-1-ND | Q18: YAGEO | R18: CC0603KRNPO9BN220 | S18: Digi-Key | T18: 311-4030-1-ND | Z18: GPC0603220-C0G
A19: 27P/0603/50V/C0G | B19: 27P/0603/50V/C0G | C19: CAP SM 0603 27pF 50V C0G | D19: GENERIC | E19: 0603 | F19: 27pF | G19: =Config!$B$4 -> SCH/C_IEC.SchLib | H19: C | I19: PCB/SMT_CHIP.PcbLib | J19: CAP0603_C0G | K19: 2.7e-11 | L19: https://www.yageo.com/upload/media/product/productsearch/datasheet/mlcc/UPY-GP_NP0_16V-to-50V_18.pdf | M19: YAGEO | N19: CC0603JRNPO9BN270 | O19: Digi-Key | P19: 311-1063-1-ND | Q19: YAGEO | R19: CC0603KRNPO9BN270 | S19: Digi-Key | T19: 311-4032-1-ND | Z19: GPC0603270-C0G
A20: 33P/0603/50V/C0G | B20: 33P/0603/50V/C0G | C20: CAP SM 0603 33pF 50V C0G | D20: GENERIC | E20: 0603 | F20: 33pF | G20: =Config!$B$4 -> SCH/C_IEC.SchLib | H20: C | I20: PCB/SMT_CHIP.PcbLib | J20: CAP0603_C0G | K20: 3.3e-11 | L20: https://www.yageo.com/upload/media/product/productsearch/datasheet/mlcc/UPY-GP_NP0_16V-to-50V_18.pdf | M20: YAGEO | N20: CC0603JRNPO9BN330 | O20: Digi-Key | P20: 311-1064-1-ND | Q20: YAGEO | R20: CC0603KRNPO9BN330 | S20: Digi-Key | T20: 311-4034-1-ND | Z20: GPC0603330-C0G
A21: 39P/0603/50V/C0G | B21: 39P/0603/50V/C0G | C21: CAP SM 0603 39pF 50V C0G | D21: GENERIC | E21: 0603 | F21: 39pF | G21: =Config!$B$4 -> SCH/C_IEC.SchLib | H21: C | I21: PCB/SMT_CHIP.PcbLib | J21: CAP0603_C0G | K21: 3.9e-11 | L21: https://www.yageo.com/upload/media/product/productsearch/datasheet/mlcc/UPY-GP_NP0_16V-to-50V_18.pdf | M21: YAGEO | N21: CC0603JRNPO9BN390 | O21: Digi-Key | P21: 311-1774-1-ND | Q21: YAGEO | R21: CC0603KRNPO9BN390 | S21: Digi-Key | T21: 13-CC0603KRNPO9BN390CT-ND | Z21: GPC0603390-C0G
A22: 47P/0603/50V/C0G | B22: 47P/0603/50V/C0G | C22: CAP SM 0603 47pF 50V C0G | D22: GENERIC | E22: 0603 | F22: 47pF | G22: =Config!$B$4 -> SCH/C_IEC.SchLib | H22: C | I22: PCB/SMT_CHIP.PcbLib | J22: CAP0603_C0G | K22: 4.7e-11 | L22: https://www.yageo.com/upload/media/product/productsearch/datasheet/mlcc/UPY-GP_NP0_16V-to-50V_18.pdf | M22: YAGEO | N22: CC0603JRNPO9BN470 | O22: Digi-Key | P22: 311-1065-1-ND | Q22: YAGEO | R22: CC0603KRNPO9BN470 | S22: Digi-Key | T22: 311-4037-1-ND | U22: Samsung Electro-Mechanics | V22: CL10C470JB8NNNC | W22: LCSC | X22: C1671 | Y22: Basic | Z22: GPC0603470-C0G
A23: 56P/0603/50V/C0G | B23: 56P/0603/50V/C0G | C23: CAP SM 0603 56pF 50V C0G | D23: GENERIC | E23: 0603 | F23: 56pF | G23: =Config!$B$4 -> SCH/C_IEC.SchLib | H23: C | I23: PCB/SMT_CHIP.PcbLib | J23: CAP0603_C0G | K23: 5.6e-11 | L23: https://www.yageo.com/upload/media/product/productsearch/datasheet/mlcc/UPY-GP_NP0_16V-to-50V_18.pdf | M23: YAGEO | N23: CC0603JRNPO9BN560 | O23: Digi-Key | P23: 311-1066-1-ND | Q23: YAGEO | R23: CC0603GRNPO9BN560 | S23: Digi-Key | T23: 311-3936-1-ND | Z23: GPC0603560-C0G
A24: 68P/0603/50V/C0G | B24: 68P/0603/50V/C0G | C24: CAP SM 0603 68pF 50V C0G | D24: GENERIC | E24: 0603 | F24: 68pF | G24: =Config!$B$4 -> SCH/C_IEC.SchLib | H24: C | I24: PCB/SMT_CHIP.PcbLib | J24: CAP0603_C0G | K24: 6.8e-11 | L24: https://www.yageo.com/upload/media/product/productsearch/datasheet/mlcc/UPY-GP_NP0_16V-to-50V_18.pdf | M24: YAGEO | N24: CC0603JRNPO9BN680 | O24: Digi-Key | P24: 311-1067-1-ND | Q24: YAGEO | R24: CC0603KRNPO9BN680 | S24: Digi-Key | T24: 311-4039-1-ND | Z24: GPC0603680-C0G
A25: 82P/0603/50V/C0G | B25: 82P/0603/50V/C0G | C25: CAP SM 0603 82pF 50V C0G | D25: GENERIC | E25: 0603 | F25: 82pF | G25: =Config!$B$4 -> SCH/C_IEC.SchLib | H25: C | I25: PCB/SMT_CHIP.PcbLib | J25: CAP0603_C0G | K25: 8.2e-11 | L25: https://www.yageo.com/upload/media/product/productsearch/datasheet/mlcc/UPY-GP_NP0_16V-to-50V_18.pdf | M25: YAGEO | N25: CC0603JRNPO9BN820 | O25: Digi-Key | P25: 311-1068-1-ND | Q25: YAGEO | R25: CC0603GRNPO9BN820 | S25: Digi-Key | T25: 311-3940-1-ND | Z25: GPC0603820-C0G
A26: 100P/0603/50V/C0G | B26: 100P/0603/50V/C0G | C26: CAP SM 0603 100pF 50V C0G | D26: GENERIC | E26: 0603 | F26: 100pF | G26: =Config!$B$4 -> SCH/C_IEC.SchLib | H26: C | I26: PCB/SMT_CHIP.PcbLib | J26: CAP0603_C0G | K26: 1e-10 | L26: https://www.yageo.com/upload/media/product/productsearch/datasheet/mlcc/UPY-GP_NP0_16V-to-50V_18.pdf | M26: YAGEO | N26: CC0603JRNPO9BN101 | O26: Digi-Key | P26: 311-1069-1-ND | Q26: YAGEO | R26: CC0603KRNPO9BN101 | S26: Digi-Key | T26: 311-3600-1-ND | U26: Samsung Electro-Mechanics | V26: CL10C101JB8NNNC | W26: LCSC | X26: C14858 | Y26: Basic | Z26: GPC0603101-C0G
A27: 120P/0603/50V/C0G | B27: 120P/0603/50V/C0G | C27: CAP SM 0603 120pF 50V C0G | D27: GENERIC | E27: 0603 | F27: 120pF | G27: =Config!$B$4 -> SCH/C_IEC.SchLib | H27: C | I27: PCB/SMT_CHIP.PcbLib | J27: CAP0603_C0G | K27: 1.2e-10 | L27: https://www.yageo.com/upload/media/product/productsearch/datasheet/mlcc/UPY-GP_NP0_16V-to-50V_18.pdf | M27: YAGEO | N27: CC0603JRNPO9BN121 | O27: Digi-Key | P27: 311-1070-1-ND | Q27: YAGEO | R27: CC0603GRNPO9BN121 | S27: Digi-Key | T27: 311-3918-1-ND | Z27: GPC0603121-C0G
A28: 150P/0603/50V/C0G | B28: 150P/0603/50V/C0G | C28: CAP SM 0603 150pF 50V C0G | D28: GENERIC | E28: 0603 | F28: 150pF | G28: =Config!$B$4 -> SCH/C_IEC.SchLib | H28: C | I28: PCB/SMT_CHIP.PcbLib | J28: CAP0603_C0G | K28: 1.5e-10 | L28: https://www.yageo.com/upload/media/product/productsearch/datasheet/mlcc/UPY-GP_NP0_16V-to-50V_18.pdf | M28: YAGEO | N28: CC0603JRNPO9BN151 | O28: Digi-Key | P28: 311-1071-1-ND | Q28: YAGEO | R28: CC0603KRNPO9BN151 | S28: Digi-Key | T28: 311-4029-1-ND | Z28: GPC0603151-C0G
A29: 180P/0603/50V/C0G | B29: 180P/0603/50V/C0G | C29: CAP SM 0603 180pF 50V C0G | D29: GENERIC | E29: 0603 | F29: 180pF | G29: =Config!$B$4 -> SCH/C_IEC.SchLib | H29: C | I29: PCB/SMT_CHIP.PcbLib | J29: CAP0603_C0G | K29: 1.8e-10 | L29: https://www.yageo.com/upload/media/product/productsearch/datasheet/mlcc/UPY-GP_NP0_16V-to-50V_18.pdf | M29: YAGEO | N29: CC0603JRNPO9BN181 | O29: Digi-Key | P29: 311-1072-1-ND | Q29: YAGEO | R29: CC0603GRNPO9BN181 | S29: Digi-Key | T29: 311-3923-1-ND | Z29: GPC0603181-C0G
A30: 220P/0603/50V/C0G | B30: 220P/0603/50V/C0G | C30: CAP SM 0603 220pF 50V C0G | D30: GENERIC | E30: 0603 | F30: 220pF | G30: =Config!$B$4 -> SCH/C_IEC.SchLib | H30: C | I30: PCB/SMT_CHIP.PcbLib | J30: CAP0603_C0G | K30: 2.2e-10 | L30: https://www.yageo.com/upload/media/product/productsearch/datasheet/mlcc/UPY-GP_NP0_16V-to-50V_18.pdf | M30: YAGEO | N30: CC0603JRNPO9BN221 | O30: Digi-Key | P30: 311-1073-1-ND | Q30: YAGEO | R30: CC0603KRNPO9BN221 | S30: Digi-Key | T30: 311-4031-1-ND | Z30: GPC0603221-C0G
A31: 270P/0603/50V/C0G | B31: 270P/0603/50V/C0G | C31: CAP SM 0603 270pF 50V C0G | D31: GENERIC | E31: 0603 | F31: 270pF | G31: =Config!$B$4 -> SCH/C_IEC.SchLib | H31: C | I31: PCB/SMT_CHIP.PcbLib | J31: CAP0603_C0G | K31: 2.7e-10 | L31: https://www.yageo.com/upload/media/product/productsearch/datasheet/mlcc/UPY-GP_NP0_16V-to-50V_18.pdf | M31: YAGEO | N31: CC0603JRNPO9BN271 | O31: Digi-Key | P31: 311-1074-1-ND | Q31: YAGEO | R31: CC0603KRNPO9BN271 | S31: Digi-Key | T31: 311-4033-1-ND | Z31: GPC0603271-C0G
A32: 330P/0603/50V/C0G | B32: 330P/0603/50V/C0G | C32: CAP SM 0603 330pF 50V C0G | D32: GENERIC | E32: 0603 | F32: 330pF | G32: =Config!$B$4 -> SCH/C_IEC.SchLib | H32: C | I32: PCB/SMT_CHIP.PcbLib | J32: CAP0603_C0G | K32: 3.3e-10 | L32: https://www.yageo.com/upload/media/product/productsearch/datasheet/mlcc/UPY-GP_NP0_16V-to-50V_18.pdf | M32: YAGEO | N32: CC0603JRNPO9BN331 | O32: Digi-Key | P32: 311-1075-1-ND | Q32: YAGEO | R32: CC0603KRNPO9BN331 | S32: Digi-Key | T32: 311-4035-1-ND | Z32: GPC0603331-C0G
A33: 390P/0603/50V/C0G | B33: 390P/0603/50V/C0G | C33: CAP SM 0603 390pF 50V C0G | D33: GENERIC | E33: 0603 | F33: 390pF | G33: =Config!$B$4 -> SCH/C_IEC.SchLib | H33: C | I33: PCB/SMT_CHIP.PcbLib | J33: CAP0603_C0G | K33: 3.9e-10 | L33: https://www.yageo.com/upload/media/product/productsearch/datasheet/mlcc/UPY-GP_NP0_16V-to-50V_18.pdf | M33: YAGEO | N33: CC0603JRNPO9BN391 | O33: Digi-Key | P33: 311-1076-1-ND | Q33: YAGEO | R33: CC0603KRNPO9BN391 | S33: Digi-Key | T33: 311-4036-1-ND | Z33: GPC0603391-C0G
A34: 470P/0603/50V/C0G | B34: 470P/0603/50V/C0G | C34: CAP SM 0603 470pF 50V C0G | D34: GENERIC | E34: 0603 | F34: 470pF | G34: =Config!$B$4 -> SCH/C_IEC.SchLib | H34: C | I34: PCB/SMT_CHIP.PcbLib | J34: CAP0603_C0G | K34: 4.7e-10 | L34: https://www.yageo.com/upload/media/product/productsearch/datasheet/mlcc/UPY-GP_NP0_16V-to-50V_18.pdf | M34: YAGEO | N34: CC0603JRNPO9BN471 | O34: Digi-Key | P34: 311-1520-1-ND | Q34: YAGEO | R34: CC0603KRNPO9BN471 | S34: Digi-Key | T34: 311-4038-1-ND | U34: Walsin Tech Corp | V34: MT18N471J500CT | W34: LCSC | X34: c458969 | Y34: Extended | Z34: GPC0603471-C0G
A35: 560P/0603/50V/C0G | B35: 560P/0603/50V/C0G | C35: CAP SM 0603 560pF 50V C0G | D35: GENERIC | E35: 0603 | F35: 560pF | G35: =Config!$B$4 -> SCH/C_IEC.SchLib | H35: C | I35: PCB/SMT_CHIP.PcbLib | J35: CAP0603_C0G | K35: 5.6e-10 | L35: https://www.yageo.com/upload/media/product/productsearch/datasheet/mlcc/UPY-GP_NP0_16V-to-50V_18.pdf | M35: YAGEO | N35: CC0603JRNPO9BN561 | O35: Digi-Key | P35: 311-3359-1-ND | Q35: YAGEO | R35: CC0603GRNPO9BN561 | S35: Digi-Key | T35: 311-3937-1-ND | U35: YAGEO | V35: CC0603JRNPO9BN561 | W35: LCSC | X35: C107054 | Y35: Extended | Z35: GPC0603561-C0G
A36: 680P/0603/50V/C0G | B36: 680P/0603/50V/C0G | C36: CAP SM 0603 680pF 50V C0G | D36: GENERIC | E36: 0603 | F36: 680pF | G36: =Config!$B$4 -> SCH/C_IEC.SchLib | H36: C | I36: PCB/SMT_CHIP.PcbLib | J36: CAP0603_C0G | K36: 6.8e-10 | L36: https://www.yageo.com/upload/media/product/productsearch/datasheet/mlcc/UPY-GP_NP0_16V-to-50V_18.pdf | M36: YAGEO | N36: CC0603JRNPO9BN681 | O36: Digi-Key | P36: 311-1425-1-ND | Q36: YAGEO | R36: CC0603GRNPO9BN681 | S36: Digi-Key | T36: 311-3939-1-ND | Z36: GPC0603681-C0G
A37: 820P/0603/50V/C0G | B37: 820P/0603/50V/C0G | C37: CAP SM 0603 820pF 50V C0G | D37: GENERIC | E37: 0603 | F37: 820pF | G37: =Config!$B$4 -> SCH/C_IEC.SchLib | H37: C | I37: PCB/SMT_CHIP.PcbLib | J37: CAP0603_C0G | K37: 8.2e-10 | L37: https://www.yageo.com/upload/media/product/productsearch/datasheet/mlcc/UPY-GP_NP0_16V-to-50V_18.pdf | M37: YAGEO | N37: CC0603JRNPO9BN821 | O37: Digi-Key | P37: 311-1775-1-ND | Q37: YAGEO | R37: CC0603GRNPO9BN821 | S37: Digi-Key | T37: 311-3941-1-ND | Z37: GPC0603821-C0G
A38: 1N/0603/50V/C0G | B38: 1N/0603/50V/C0G | C38: CAP SM 0603 1.0nF 50V C0G | D38: GENERIC | E38: 0603 | F38: 1.0nF | G38: =Config!$B$4 -> SCH/C_IEC.SchLib | H38: C | I38: PCB/SMT_CHIP.PcbLib | J38: CAP0603_C0G | K38: 1e-09 | L38: https://www.yageo.com/upload/media/product/productsearch/datasheet/mlcc/UPY-GP_NP0_16V-to-50V_18.pdf | M38: YAGEO | N38: CC0603JRNPO9BN102 | O38: Digi-Key | P38: 311-1423-1-ND | Q38: YAGEO | R38: CC0603KRNPO9BN102 | S38: Digi-Key | T38: 311-4026-1-ND | U38: TDK | V38: C1608C0G1H102JT000N | W38: LCSC | X38: C342541 | Y38: Extended | Z38: GPC0603102-C0G
A39: 1N2/0603/50V/C0G | B39: 1N2/0603/50V/C0G | C39: CAP SM 0603 1.2nF 50V C0G | D39: GENERIC | E39: 0603 | F39: 1.2nF | G39: =Config!$B$4 -> SCH/C_IEC.SchLib | H39: C | I39: PCB/SMT_CHIP.PcbLib | J39: CAP0603_C0G | K39: 1.2e-09 | L39: https://www.yageo.com/upload/media/product/productsearch/datasheet/mlcc/UPY-GP_NP0_16V-to-50V_18.pdf | M39: YAGEO | N39: CC0603JRNPO9BN122 | O39: Digi-Key | P39: 311-3962-1-ND | Q39: YAGEO | R39: CC0603GRNPO9BN122 | S39: Digi-Key | T39: 13-CC0603GRNPO9BN122CT-ND | Z39: GPC0603122-C0G
A40: 1N5/0603/50V/C0G | B40: 1N5/0603/50V/C0G | C40: CAP SM 0603 1.5nF 50V C0G | D40: GENERIC | E40: 0603 | F40: 1.5nF | G40: =Config!$B$4 -> SCH/C_IEC.SchLib | H40: C | I40: PCB/SMT_CHIP.PcbLib | J40: CAP0603_C0G | K40: 1.5e-09 | L40: https://www.yageo.com/upload/media/product/productsearch/datasheet/mlcc/UPY-GP_NP0_16V-to-50V_18.pdf | M40: YAGEO | N40: CC0603JRNPO9BN152 | O40: Digi-Key | P40: 311-1768-1-ND | Q40: YAGEO | R40: CC0603GRNPO9BN152 | S40: Digi-Key | T40: 13-CC0603GRNPO9BN152CT-ND | Z40: GPC0603152-C0G
...

Sheet L
A1: Part Number | B1: Comment | C1: Description | D1: Manufacturer | E1: Package | F1: Value | G1: Library Path | H1: Library Ref | I1: Footprint Path | J1: Footprint Ref | K1: Absolute Value | L1: HelpURL | M1: Manufacturer 1 | N1: Manufacturer Part Number 1 | O1: Supplier 1 | P1: Supplier Part Number 1 | Q1: Manufacturer 2 | R1: Manufacturer Part Number 2 | S1: Supplier 2 | T1: Supplier Part Number 2 | U1: Manufacturer 3 | V1: Manufacturer Part Number 3 | W1: Supplier 3 | X1: Supplier Part Number 3 | Y1: JLC Type
A2: 470NH/2520 | B2: 470NH/2520 | C2: 0.47UH 2520 Shielded Inductor SMD | D2: GENERIC | E2: 2520 metric | F2: 470NH | G2: =Config!$B$5 -> SCH/L_ANSI.SchLib | H2: L | I2: PCB/IND_SMT.PcbLib | J2: INDM2520X10 | K2: 4.7e-07 | L2: https://mm.digikey.com/Volume0/opasdata/d220001/medias/docus/5561/WIP252010S%20L%20Series.pdf | M2: INPAQ Technology Co., Ltd | N2: WIP252010S-R47MLDG | O2: Digi-Key | P2: 3526-WIP252010S-R47MLDGCT-ND | U2: INPAQ | V2: WIP252010S-R47ML | W2: LCSC | X2: C964116 | Y2: Extended
A3: 680NH/2520 | B3: 680NH/2520 | C3: 0.68UH 2520 Shielded Inductor SMD | D3: GENERIC | E3: 2520 metric | F3: 680NH | G3: =Config!$B$5 -> SCH/L_ANSI.SchLib | H3: L | I3: PCB/IND_SMT.PcbLib | J3: INDM2520X10 | K3: 6.8e-07 | L3: https://mm.digikey.com/Volume0/opasdata/d220001/medias/docus/5561/WIP252010S%20L%20Series.pdf | M3: INPAQ Technology Co., Ltd | N3: WIP252010S-R68MLDG | O3: Digi-Key | P3: 3526-WIP252010S-R68MLDGCT-ND | U3: TDK | V3: VLS252010HBX-R68M | W3: LCSC | X3: C307862 | Y3: Extended
A4: 1UH/2520 | B4: 1UH/2520 | C4: 1UH 2520 Shielded Inductor SMD | D4: GENERIC | E4: 2520 metric | F4: 1UH | G4: =Config!$B$5 -> SCH/L_ANSI.SchLib | H4: L | I4: PCB/IND_SMT.PcbLib | J4: INDM2520X10 | K4: 1e-06 | L4: https://mm.digikey.com/Volume0/opasdata/d220001/medias/docus/5561/WIP252010S%20L%20Series.pdf | M4: INPAQ Technology Co., Ltd | N4: WIP252010S-1R0MLDG | O4: Digi-Key | P4: 3526-WIP252010S-1R0MLDGCT-ND | U4: INPAQ | V4: WIP252012P-1R0ML | W4: LCSC | X4: C315711 | Y4: Extended
A5: 1UH5/2520 | B5: 1UH5/2520 | C5: 1.5UH 2520 Shielded Inductor SMD | D5: GENERIC | E5: 2520 metric | F5: 1.5UH | G5: =Config!$B$5 -> SCH/L_ANSI.SchLib | H5: L | I5: PCB/IND_SMT.PcbLib | J5: INDM2520X10 | K5: 1.5e-06 | L5: https://mm.digikey.com/Volume0/opasdata/d220001/medias/docus/5561/WIP252010S%20L%20Series.pdf | M5: INPAQ Technology Co., Ltd | N5: WIP252010S-1R5MLDG | O5: Digi-Key | P5: 3526-WIP252010S-1R5MLDGCT-ND | U5: INPAQ | V5: WIP252012P-1R5ML | W5: LCSC | X5: C964121 | Y5: Extended
A6: 2UH2/2520 | B6: 2UH2/2520 | C6: 2.2UH 2520 Shielded Inductor SMD | D6: GENERIC | E6: 2520 metric | F6: 2.2UH | G6: =Config!$B$5 -> SCH/L_ANSI.SchLib | H6: L | I6: PCB/IND_SMT.PcbLib | J6: INDM2520X10 | K6: 2.2e-06 | L6: https://mm.digikey.com/Volume0/opasdata/d220001/medias/docus/5561/WIP252010S%20L%20Series.pdf | M6: INPAQ Technology Co., Ltd | N6: WIP252010S-2R2MLDG | O6: Digi-Key | P6: 3526-WIP252010S-2R2MLDGCT-ND | U6: INPAQ | V6: WIP252010S-2R2ML | W6: LCSC | X6: C964118
A7: 4UH7/2520 | B7: 4UH7/2520 | C7: 4.7UH 2520 Shielded Inductor SMD | D7: GENERIC | E7: 2520 metric | F7: 4.7UH | G7: =Config!$B$5 -> SCH/L_ANSI.SchLib | H7: L | I7: PCB/IND_SMT.PcbLib | J7: INDM2520X10 | K7: 4.7e-06 | L7: https://mm.digikey.com/Volume0/opasdata/d220001/medias/docus/5561/WIP252010S%20L%20Series.pdf | M7: INPAQ Technology Co., Ltd | N7: WIP252010S-4R7MLDG | O7: Digi-Key | P7: 3526-WIP252010S-4R7MLDGCT-ND | U7: INPAQ | V7: WIP252010S-4R7ML | W7: LCSC | X7: C19631658
A8: 240NH/2016 | B8: 240NH/2016 | C8: 240NH 2016 Shielded Inductor SMD | D8: GENERIC | E8: 2016 metric | F8: 240NH | G8: =Config!$B$5 -> SCH/L_ANSI.SchLib | H8: L | I8: PCB/IND_SMT.PcbLib | J8: INDM2016X10 | K8: 2.4e-07 | L8: https://mm.digikey.com/Volume0/opasdata/d220001/medias/docus/5561/WIP201610S%20L%20Series.pdf | M8: INPAQ Technology Co., Ltd | N8: WIP201610S-R24MLDG | O8: Digi-Key | P8: 3526-WIP201610S-R24MLDGCT-ND | U8: INPAQ | V8: WIP201610P-R24ML | W8: LCSC | X8: C964103 | Y8: Extended
A9: 330NH/2016 | B9: 330NH/2016 | C9: 330NH 2016 Shielded Inductor SMD | D9: GENERIC | E9: 2016 metric | F9: 330NH | G9: =Config!$B$5 -> SCH/L_ANSI.SchLib | H9: L | I9: PCB/IND_SMT.PcbLib | J9: INDM2016X10 | K9: 3.3e-07 | L9: https://mm.digikey.com/Volume0/opasdata/d220001/medias/docus/5561/WIP201610S%20L%20Series.pdf | M9: INPAQ Technology Co., Ltd | N9: WIP201610S-R33MLDG | O9: Digi-Key | P9: 3526-WIP201610S-R33MLDGCT-ND | U9: INPAQ | V9: WIP201610P-R33ML | W9: LCSC | X9: C964104 | Y9: Extended
A10: 470NH/2016 | B10: 470NH/2016 | C10: 470NH 2016 Shielded Inductor SMD | D10: GENERIC | E10: 2016 metric | F10: 470NH | G10: =Config!$B$5 -> SCH/L_ANSI.SchLib | H10: L | I10: PCB/IND_SMT.PcbLib | J10: INDM2016X10 | K10: 4.7e-07 | L10: https://mm.digikey.com/Volume0/opasdata/d220001/medias/docus/5561/WIP201610S%20L%20Series.pdf | M10: INPAQ Technology Co., Ltd | N10: WIP201610S-R47MLDG | O10: Digi-Key | P10: 3526-WIP201610S-R47MLDGCT-ND | U10: INPAQ | V10: WIP201610P-R47ML | W10: LCSC | X10: C964105 | Y10: Extended
A11: 680NH/2016 | B11: 680NH/2016 | C11: 680NH 2016 Shielded Inductor SMD | D11: GENERIC | E11: 2016 metric | F11: 680NH | G11: =Config!$B$5 -> SCH/L_ANSI.SchLib | H11: L | I11: PCB/IND_SMT.PcbLib | J11: INDM2016X10 | K11: 6.8e-07 | L11: https://mm.digikey.com/Volume0/opasdata/d220001/medias/docus/5561/WIP201610S%20L%20Series.pdf | M11: INPAQ Technology Co., Ltd | N11: WIP201610S-R68MLDG | O11: Digi-Key | P11: 3526-WIP201610S-R68MLDGCT-ND | U11: INPAQ | V11: WIP201610P-R68ML | W11: LCSC | X11: C315716 | Y11: Extended
A12: 1UH/2016 | B12: 1UH/2016 | C12: 1UH 2016 Shielded Inductor SMD | D12: GENERIC | E12: 2016 metric | F12: 1UH | G12: =Config!$B$5 -> SCH/L_ANSI.SchLib | H12: L | I12: PCB/IND_SMT.PcbLib | J12: INDM2016X10 | K12: 1e-06 | L12: https://mm.digikey.com/Volume0/opasdata/d220001/medias/docus/5561/WIP201610S%20L%20Series.pdf | M12: INPAQ Technology Co., Ltd | N12: WIP201610S-1R0MLDG | O12: Digi-Key | P12: 3526-WIP201610S-1R0MLDGCT-ND | U12: INPAQ | V12: WIP201610P-1R0ML | W12: LCSC | X12: C315718 | Y12: Extended
A13: 1UH5/2016 | B13: 1UH5/2016 | C13: 1.5UH 2016 Shielded Inductor SMD | D13: GENERIC | E13: 2016 metric | F13: 1.5UH | G13: =Config!$B$5 -> SCH/L_ANSI.SchLib | H13: L | I13: PCB/IND_SMT.PcbLib | J13: INDM2016X10 | K13: 1.5e-06 | L13: https://mm.digikey.com/Volume0/opasdata/d220001/medias/docus/5561/WIP201610S%20L%20Series.pdf | M13: INPAQ Technology Co., Ltd | N13: WIP201610S-1R5MLDG | O13: Digi-Key | P13: 3526-WIP201610S-1R5MLDGCT-ND | U13: INPAQ | V13: WIP201610P-1R5ML | W13: LCSC | X13: C964106
A14: 2UH2/2016 | B14: 2UH2/2016 | C14: 2.2UH 2016 Shielded Inductor SMD | D14: GENERIC | E14: 2016 metric | F14: 2.2UH | G14: =Config!$B$5 -> SCH/L_ANSI.SchLib | H14: L | I14: PCB/IND_SMT.PcbLib | J14: INDM2016X10 | K14: 2.2e-06 | L14: https://mm.digikey.com/Volume0/opasdata/d220001/medias/docus/5561/WIP201610S%20L%20Series.pdf | M14: INPAQ Technology Co., Ltd | N14: WIP201610S-2R2MLDG | O14: Digi-Key | P14: 3526-WIP201610S-2R2MLDGCT-ND | U14: INPAQ | V14: WIP201610P-2R2ML | W14: LCSC | X14: C315717 | Y14: Extended
A15: 1K/0603/FERRITE | B15: 1K/0603/FERRITE | C15: 1K@100MHz 800mA 0603 Ferrite | D15: GENERIC | E15: 603 | F15: 1K | G15: =Config!$B$5 -> SCH/L_ANSI.SchLib | H15: Ferrite | I15: PCB/SMT_CHIP.PcbLib | J15: FB0603 | K15: 1000 | L15: https://product.tdk.com/en/system/files?file=dam/doc/product/emc/emc/beads/catalog/beads_automotive_power_mpz1608_en.pdf | M15: TDK Corporation | N15: MPZ1608S102ATD25 | O15: Digi-Key | P15: 445-MPZ1608S102ATD25CT-ND | U15: TAI-TECH | V15: FCM1608KF-102T08 | W15: LCSC | X15: C2880084
A16: 51UH/1812/CMC | B16: 51UH/1812/CMC | C16: 51uH 230mA Common mode choke | D16: GENERIC | E16: 1812 | F16: 51UH | G16: =Config!$B$5 -> SCH/L_ANSI.SchLib | H16: L_CMC_2 | I16: PCB/IND_SMT.PcbLib | J16: CMC4532X260 | K16: 5.1e-05 | L16: https://www.murata.com/en-eu/products/productdata/8796758605854/QFLC9101.pdf | M16: TAI-TECH Advanced Electronics Co., Ltd. | N16: ACM 4532F2NV-510T02-D | O16: Digi-Key | P16: 4816-ACM4532F2NV-510T02-DCT-ND | U16: TAI-TECH | V16: ACM4532F2NV-510T02-D | W16: LCSC | X16: C2880054
A17: 220UH/SRR1280 | B17: 220UH/SRR1280 | C17: FIXED IND 220UH 1.6A 400MOHM SMD | D17: Buorns Inc | E17: 12.5x12.5mm | F17: 220UH | G17: =Config!$B$5 -> SCH/L_ANSI.SchLib | H17: L | I17: PCB/IND_SMT.PcbLib | J17: INDM125125X800 | K17: 0.00022 | L17: https://www.bourns.com/docs/Product-Datasheets/SRR1280.pdf | M17: Buorns Inc | N17: SRR1280-221K | O17: Digi-Key | P17: SRR1280-221KLCT-ND | U17: XR | V17: XRRH129-221M | W17: LCSC | X17: C5339683
A18: 2UH2/SRP5015TA | B18: 2UH2/SRP5015TA | C18: FIXED IND 2.2UH 4A 52 MOHM SMD | D18: Buorns Inc | E18: 5.7x5.2mm | F18: 2.2UH | G18: =Config!$B$5 -> SCH/L_ANSI.SchLib | H18: L | I18: PCB/IND_SMT.PcbLib | J18: INDM5752X130 | K18: 2.2e-06 | L18: https://www.bourns.com/docs/Product-Datasheets/SRP5015TA.pdf | M18: Buorns Inc | N18: SRP5015TA-2R2M | O18: Digi-Key | P18: SRP5015TA-2R2MCT-ND | U18: YJYCOIN | V18: YSPI0520-2R2M | W18: LCSC | X18: C718375
A19: HX2019NL | B19: HX2019NL | C19: MODULE MAGNETICS POE SINGLE VOIP | D19: Pulse Electronics | G19: =Config!$B$5 -> SCH/L_ANSI.SchLib | H19: Pulse_2Channel_CT | I19: PCB/IND_SMT.PcbLib | J19: XFMR_HX2019 | L19: https://productfinder.pulseelectronics.com/api/open/part-attachments/datasheet/HX2019NL | M19: Pulse Electronics | N19: HX2019NL | O19: Digi-Key | P19: 553-1616-5-ND | U19: Pulse Elec | V19: HX2019NLT | W19: LCSC | X19: C2977267
A20: LAN2VSOPS24351C2 | B20: LAN2VSOPS24351C2 | C20: 350µH LAN 1000 Base-T, Power over Ethernet (PoE) Pulswandler 1CT:1CT Oberflächenmontage | D20: Eaton | G20: =Config!$B$5 -> SCH/L_ANSI.SchLib | H20: Pulse_4Channel_CT | I20: PCB/IND_SMT.PcbLib | J20: IND127P1600X620-24 | L20: https://www.eaton.com/content/dam/eaton/products/electronic-components/resources/data-sheet/eaton-lan2vsop-1000-base-t-lan-transformer-poe-data-sheet-elx1376-en.pdf | M20: Eaton | N20: LAN2VSOPS24351C2 | O20: Digi-Key | P20: 283-LAN2VSOPS24351C2CT-ND | U20: CND-tek | V20: G2412S | W20: LCSC | X20: C2912224
A21: LAN2VSOPD48351C2 | B21: LAN2VSOPD48351C2 | C21: 350µH LAN 1000 Base-T, Power over Ethernet (PoE) Pulswandler 1CT:1CT Oberflächenmontage | D21: Eaton | G21: =Config!$B$5 -> SCH/L_ANSI.SchLib | H21: Pulse_8Channel_CT | I21: PCB/IND_SMT.PcbLib | J21: IND102P1524X750-48 | L21: https://www.eaton.com/content/dam/eaton/products/electronic-components/resources/data-sheet/eaton-lan2vsop-1000-base-t-lan-transformer-poe-data-sheet-elx1376-en.pdf | M21: Eaton | N21: LAN2VSOPD48351C2 | O21: Digi-Key | P21: 283-LAN2VSOPD48351C2CT-ND | U21: CND-tek | V21: G4812S | W21: LCSC | X21: C3003221
A22: 15UH/1510 | B22: 15UH/1510 | C22: 15UH fixed inductor shielded | D22: GENERIC | E22: 1510 | F22: 15UH | G22: =Config!$B$5 -> SCH/L_ANSI.SchLib | H22: L | I22: PCB/IND_SMT.PcbLib | J22: INDM165155X100 | K22: 1.5e-05 | L22: https://www.bourns.com/docs/product-datasheets/srp1510ca.pdf | M22: Buorns Inc | N22: SRP1510CA-150M | O22: Digi-Key | P22: SRP1510CA-150M | U22: Coilcraft | V22: XAL1510-153MED | W22: LCSC | X22: C3911455
A23: 10UH/6630 | B23: 10UH/6630 | C23: FIXED IND 10UH 4A 68 MOHM SMD | D23: GENERIC | E23: 6030 | F23: 10UH | G23: =Config!$B$5 -> SCH/L_ANSI.SchLib | H23: L | I23: PCB/IND_SMT.PcbLib | J23: INDM660730X30 | K23: 1e-05 | L23: https://productfinder.pulseelectronics.com/api/open/part-attachments/datasheet/BMRB00060630100MA1 | M23: Pulse Electronics | N23: BMRB00060630100MA1 | O23: Digi-Key | P23: 553-BMRB00060630100MA1CT-ND | U23: Chilisin Elec | V23: BMRB00060630100MA1 | W23: LCSC | X23: C5201679
A24: 220NH/6630 | B24: 220NH/6630 | C24: FIXED IND 220NH 23 A 2.8 MOHM SMD | D24: GENERIC | E24: 6030 | F24: 220NH | G24: =Config!$B$5 -> SCH/L_ANSI.SchLib | H24: L | I24: PCB/IND_SMT.PcbLib | J24: INDM660730X30 | K24: 2.2e-07 | L24: https://productfinder.pulseelectronics.com/api/open/part-attachments/datasheet/BMRA00060630R22MA1 | M24: Pulse Electronics | N24: BMRA00060630R22MA1 | O24: Digi-Key | P24: 553-BMRA00060630R22MA1CT-ND
A25: 330NH/6630 | B25: 330NH/6630 | C25: FIXED IND 330NH 20 A 4.2 MOHM SMD | D25: GENERIC | E25: 6030 | F25: 330NH | G25: =Config!$B$5 -> SCH/L_ANSI.SchLib | H25: L | I25: PCB/IND_SMT.PcbLib | J25: INDM660730X30 | K25: 3.3e-07 | L25: https://productfinder.pulseelectronics.com/api/open/part-attachments/datasheet/BMRA00060630R33MA1 | M25: Pulse Electronics | N25: BMRA00060630R33MA1 | O25: Digi-Key | P25: 553-BMRA00060630R33MA1CT-ND
A26: 470NH/6630 | B26: 470NH/6630 | C26: FIXED IND 470NH 16.5 A 5.5 MOHM SMD | D26: GENERIC | E26: 6030 | F26: 470NH | G26: =Config!$B$5 -> SCH/L_ANSI.SchLib | H26: L | I26: PCB/IND_SMT.PcbLib | J26: INDM660730X30 | K26: 4.7e-07 | L26: https://productfinder.pulseelectronics.com/api/open/part-attachments/datasheet/BMRA00060630R47MA1 | M26: Pulse Electronics | N26: BMRA00060630R47MA1 | O26: Digi-Key | P26: 553-BMRA00060630R47MA1CT-ND
A27: 680NH/6630 | B27: 680NH/6630 | C27: FIXED IND 680NH 16.5 A 6.3 MOHM SMD | D27: GENERIC | E27: 6030 | F27: 680NH | G27: =Config!$B$5 -> SCH/L_ANSI.SchLib | H27: L | I27: PCB/IND_SMT.PcbLib | J27: INDM660730X30 | K27: 6.8e-07 | L27: https://productfinder.pulseelectronics.com/api/open/part-attachments/datasheet/BMRA00060630R68MA1 | M27: Pulse Electronics | N27: BMRA00060630R68MA1 | O27: Digi-Key | P27: 553-BMRA00060630R68MA1CT-ND
A28: 1UH/6630 | B28: 1UH/6630 | C28: FIXED IND 1UH 15 A 10 MOHM SMD | D28: GENERIC | E28: 6030 | F28: 1UH | G28: =Config!$B$5 -> SCH/L_ANSI.SchLib | H28: L | I28: PCB/IND_SMT.PcbLib | J28: INDM660730X30 | K28: 1e-06 | L28: https://productfinder.pulseelectronics.com/api/open/part-attachments/datasheet/BMRA000606301R0MA1 | M28: Pulse Electronics | N28: BMRA000606301R0MA1 | O28: Digi-Key | P28: 553-BMRA000606301R0MA1CT-ND
A29: 1UH5/6630 | B29: 1UH5/6630 | C29: FIXED IND 1.5UH 12 A 15 MOHM SMD | D29: GENERIC | E29: 6030 | F29: 1.5UH | G29: =Config!$B$5 -> SCH/L_ANSI.SchLib | H29: L | I29: PCB/IND_SMT.PcbLib | J29: INDM660730X30 | K29: 1.5e-06 | L29: https://productfinder.pulseelectronics.com/api/open/part-attachments/datasheet/BMRA000606301R5MA1 | M29: Pulse Electronics | N29: BMRA000606301R5MA1 | O29: Digi-Key | P29: 553-BMRA000606301R5MA1CT-ND
A30: 2UH2/6630 | B30: 2UH2/6630 | C30: FIXED IND 2.2UH 9.5 A 20 MOHM SMD | D30: GENERIC | E30: 6030 | F30: 2.2UH | G30: =Config!$B$5 -> SCH/L_ANSI.SchLib | H30: L | I30: PCB/IND_SMT.PcbLib | J30: INDM660730X30 | K30: 2.2e-06 | L30: https://productfinder.pulseelectronics.com/api/open/part-attachments/datasheet/BMRA000606302R2MA1 | M30: Pulse Electronics | N30: BMRA000606302R2MA1 | O30: Digi-Key | P30: 553-BMRA000606302R2MA1CT-ND
A31: 3UH3/6630 | B31: 3UH3/6630 | C31: FIXED IND 3.3UH 8.5 A 35 MOHM SMD | D31: GENERIC | E31: 6030 | F31: 3.3UH | G31: =Config!$B$5 -> SCH/L_ANSI.SchLib | H31: L | I31: PCB/IND_SMT.PcbLib | J31: INDM660730X30 | K31: 3.3e-06 | L31: https://productfinder.pulseelectronics.com/api/open/part-attachments/datasheet/BMRA000606303R3MA1 | M31: Pulse Electronics | N31: BMRA000606303R3MA1 | O31: Digi-Key | P31: 553-BMRA000606303R3MA1CT-ND
A32: 4UH7/6630 | B32: 4UH7/6630 | C32: FIXED IND 4.7UH 6 A 40 MOHM SMD | D32: GENERIC | E32: 6030 | F32: 4.7UH | G32: =Config!$B$5 -> SCH/L_ANSI.SchLib | H32: L | I32: PCB/IND_SMT.PcbLib | J32: INDM660730X30 | K32: 4.7e-06 | L32: https://productfinder.pulseelectronics.com/api/open/part-attachments/datasheet/BMRA000606304R7MA1 | M32: Pulse Electronics | N32: BMRA000606304R7MA1 | O32: Digi-Key | P32: 553-BMRA000606304R7MA1CT-ND
A33: 15UH/6630 | B33: 15UH/6630 | C33: FIXED IND 15UH 5.5 A 122 MOHM SMD | D33: GENERIC | E33: 6030 | F33: 15UH | G33: =Config!$B$5 -> SCH/L_ANSI.SchLib | H33: L | I33: PCB/IND_SMT.PcbLib | J33: INDM660730X30 | K33: 1.5e-05 | L33: https://productfinder.pulseelectronics.com/api/open/part-attachments/datasheet/BMRA00060630150MA1 | M33: Pulse Electronics | N33: BMRA00060630150MA1 | O33: Digi-Key | P33: 553-BMRA00060630150MA1CT-ND
A34: 22UH/6630 | B34: 22UH/6630 | C34: FIXED IND 22UH 3 A 145 MOHM SMD | D34: GENERIC | E34: 6030 | F34: 22UH | G34: =Config!$B$5 -> SCH/L_ANSI.SchLib | H34: L | I34: PCB/IND_SMT.PcbLib | J34: INDM660730X30 | K34: 2.2e-05 | L34: https://productfinder.pulseelectronics.com/api/open/part-attachments/datasheet/BMRA00060630220MA1 | M34: Pulse Electronics | N34: BMRA00060630220MA1 | O34: Digi-Key | P34: 553-BMRA00060630220MA1CT-ND
A35: 33UH/6630 | B35: 33UH/6630 | C35: FIXED IND 33UH 3 A 270 MOHM SMD | D35: GENERIC | E35: 6030 | F35: 33UH | G35: =Config!$B$5 -> SCH/L_ANSI.SchLib | H35: L | I35: PCB/IND_SMT.PcbLib | J35: INDM660730X30 | K35: 3.3e-05 | L35: https://productfinder.pulseelectronics.com/api/open/part-attachments/datasheet/BMRA00060630330MA1 | M35: Pulse Electronics | N35: BMRA00060630330MA1 | O35: Digi-Key | P35: 553-BMRA00060630330MA1CT-ND
... A50: 22UH/1245 | B50: 22UH/1245 | C50: FIXED IND 22UH 7.5 A 58 MOHM SMD | D50: GENERIC | E50: 1245 | F50: 22UH | G50: =Config!$B$5 -> SCH/L_ANSI.SchLib | H50: L | I50: PCB/IND_SMT.PcbLib | J50: INDM126126X47 | K50: 2.2e-05 | L50: https://www.bourns.com/docs/product-datasheets/srp1245c.pdf | M50: Bourns Inc. | N50: SRP1245C-220M | O50: Digi-Key | P50: 118-SRP1245C-220MCT-ND
A51: 1MH/THT/CMC | B51: 1MH/THT/CMC | C51: CMC 1mH 2A THT Schurter DFKH-14-0003 | D51: SCHURTER | E51: 15X10.5mm | F51: 1MH | G51: =Config!$B$5 -> SCH/L_ANSI.SchLib | H51: L_CMC_2 | I51: =_xlfn.CONCAT(PrivateLibraryPath,"PCB/Schurter.PcbLib") -> ../altium_lib_private/PCB/Schurter.PcbLib | J51: DFKH-CASE-50-2 | L51: https://www.schurter.com/en/datasheet/typ_DFKH.pdf | M51: SCHURTER Inc. | N51: DFKH-14-0003 | O51: Digi-Key | P51: 486-3121-ND
A52: 30R/0603/FERRITE | B52: 30R/0603/FERRITE | C52: 30R@100MHz 5A 0603 Ferrite | D52: GENERIC | E52: 603 | F52: 30R | G52: =Config!$B$5 -> SCH/L_ANSI.SchLib | H52: Ferrite | I52: PCB/SMT_CHIP.PcbLib | J52: FB0603 | K52: 1000 | L52: https://www.laird.com/document/datasheet/hi0603r300r-10-datasheet | M52: Laird-Signal Integrity Products | N52: HI0603R300R-10 | O52: Digi-Key | P52: 240-HI0603R300R-10CT-ND
A53: 820UH/RCH-110 | B53: 820UH/RCH-110 | C53: 820UH unshielded inductor THT RCH-110 | D53: Sumida | E53: RCH-110 | F53: 820UH | G53: =Config!$B$5 -> SCH/L_ANSI.SchLib | H53: L | I53: PCB/L_THT.PcbLib | J53: RCH-110-DUAL-PAR | K53: 0.00082 | L53: https://products.sumida.com/products/pdf/RCH-110.pdf | M53: Sumida | N53: RCH110NP-821K | O53: Digi-Key
A54: 30MH/THT/CMC | B54: 30MH/THT/CMC | C54: CMC 30mH 5A Würth CMBNC 7448050530 | D54: Würth | E54: CMBNC | F54: 30MH | G54: =Config!$B$5 -> SCH/L_ANSI.SchLib | H54: L_CMC_2 | I54: PCB/L_THT.PcbLib | J54: CMC-WE-CMBNC-XL-7448050530 | K54: 0.03 | L54: https://www.we-online.com/components/products/datasheet/7448050530.pdf | M54: Würth Elektronik | N54: 7448050530 | O54: Digi-Key | P54: 732-5596-ND
...

Sheet D
